<?xml version="1.0" ?>
<robot name="demo_rover" xmlns:xacro="http://www.ros.org/wiki/xacro">

<xacro:include filename="$(find demo_rover_description)/urdf/materials.xacro" />
<xacro:include filename="$(find demo_rover_description)/urdf/demo_rover.trans" />
<xacro:include filename="$(find demo_rover_description)/urdf/demo_rover.gazebo" />
<link name="base_link">
  <inertial>
    <origin xyz="-0.007031150413168912 0.0 0.190988852993785" rpy="0 0 0"/>
    <mass value="57.69474606362084"/>
    <inertia ixx="0.881354" iyy="2.133385" izz="2.116392" ixy="-0.0" iyz="0.0" ixz="0.057857"/>
  </inertial>
  <visual>
    <origin xyz="0 0 0" rpy="0 0 0"/>
    <geometry>
      <mesh filename="package://demo_rover_description/meshes/base_link.stl" scale="0.001 0.001 0.001"/>
    </geometry>
    <material name="silver"/>
  </visual>
  <collision>
    <origin xyz="0 0 0" rpy="0 0 0"/>
    <geometry>
      <mesh filename="package://demo_rover_description/meshes/base_link.stl" scale="0.001 0.001 0.001"/>
    </geometry>
  </collision>
</link>

<link name="right_wheel_front_1">
  <inertial>
    <origin xyz="5.551115123125783e-17 -0.024999999999999994 0.0" rpy="0 0 0"/>
    <mass value="1.813091660203009"/>
    <inertia ixx="0.004049" iyy="0.007343" izz="0.004049" ixy="0.0" iyz="-0.0" ixz="-0.0"/>
  </inertial>
  <visual>
    <origin xyz="-0.175 0.15 -0.09" rpy="0 0 0"/>
    <geometry>
      <mesh filename="package://demo_rover_description/meshes/right_wheel_front_1.stl" scale="0.001 0.001 0.001"/>
    </geometry>
    <material name="silver"/>
  </visual>
  <collision>
    <origin xyz="-0.175 0.15 -0.09" rpy="0 0 0"/>
    <geometry>
      <mesh filename="package://demo_rover_description/meshes/right_wheel_front_1.stl" scale="0.001 0.001 0.001"/>
    </geometry>
  </collision>
</link>

<link name="right_wheel_behind_1">
  <inertial>
    <origin xyz="2.7755575615628914e-17 -0.024999999999999994 0.0" rpy="0 0 0"/>
    <mass value="1.813091660203009"/>
    <inertia ixx="0.004049" iyy="0.007343" izz="0.004049" ixy="0.0" iyz="-0.0" ixz="0.0"/>
  </inertial>
  <visual>
    <origin xyz="0.175 0.15 -0.09" rpy="0 0 0"/>
    <geometry>
      <mesh filename="package://demo_rover_description/meshes/right_wheel_behind_1.stl" scale="0.001 0.001 0.001"/>
    </geometry>
    <material name="silver"/>
  </visual>
  <collision>
    <origin xyz="0.175 0.15 -0.09" rpy="0 0 0"/>
    <geometry>
      <mesh filename="package://demo_rover_description/meshes/right_wheel_behind_1.stl" scale="0.001 0.001 0.001"/>
    </geometry>
  </collision>
</link>

<link name="left_wheel_behind_1">
  <inertial>
    <origin xyz="2.7755575615628914e-17 0.024999999999999994 0.0" rpy="0 0 0"/>
    <mass value="1.813091660203009"/>
    <inertia ixx="0.004049" iyy="0.007343" izz="0.004049" ixy="-0.0" iyz="0.0" ixz="0.0"/>
  </inertial>
  <visual>
    <origin xyz="0.175 -0.15 -0.09" rpy="0 0 0"/>
    <geometry>
      <mesh filename="package://demo_rover_description/meshes/left_wheel_behind_1.stl" scale="0.001 0.001 0.001"/>
    </geometry>
    <material name="silver"/>
  </visual>
  <collision>
    <origin xyz="0.175 -0.15 -0.09" rpy="0 0 0"/>
    <geometry>
      <mesh filename="package://demo_rover_description/meshes/left_wheel_behind_1.stl" scale="0.001 0.001 0.001"/>
    </geometry>
  </collision>
</link>

<link name="left_wheel_front_1">
  <inertial>
    <origin xyz="5.551115123125783e-17 0.024999999999999994 0.0" rpy="0 0 0"/>
    <mass value="1.813091660203009"/>
    <inertia ixx="0.004049" iyy="0.007343" izz="0.004049" ixy="-0.0" iyz="0.0" ixz="0.0"/>
  </inertial>
  <visual>
    <origin xyz="-0.175 -0.15 -0.09" rpy="0 0 0"/>
    <geometry>
      <mesh filename="package://demo_rover_description/meshes/left_wheel_front_1.stl" scale="0.001 0.001 0.001"/>
    </geometry>
    <material name="silver"/>
  </visual>
  <collision>
    <origin xyz="-0.175 -0.15 -0.09" rpy="0 0 0"/>
    <geometry>
      <mesh filename="package://demo_rover_description/meshes/left_wheel_front_1.stl" scale="0.001 0.001 0.001"/>
    </geometry>
  </collision>
</link>

<link name="lidar_1">
  <inertial>
    <origin xyz="-2.7755575615628914e-17 -9.650038500203382e-18 0.015000000000000013" rpy="0 0 0"/>
    <mass value="0.3251548396465435"/>
    <inertia ixx="0.000228" iyy="0.000228" izz="0.000406" ixy="-0.0" iyz="0.0" ixz="0.0"/>
  </inertial>
  <visual>
    <origin xyz="0.16 0.0 -0.39" rpy="0 0 0"/>
    <geometry>
      <mesh filename="package://demo_rover_description/meshes/lidar_1.stl" scale="0.001 0.001 0.001"/>
    </geometry>
    <material name="silver"/>
  </visual>
  <collision>
    <origin xyz="0.16 0.0 -0.39" rpy="0 0 0"/>
    <geometry>
      <mesh filename="package://demo_rover_description/meshes/lidar_1.stl" scale="0.001 0.001 0.001"/>
    </geometry>
  </collision>
</link>

<joint name="Rigid 6" type="fixed">
  <origin xyz="0.175 -0.15 0.09" rpy="0 0 0"/>
  <parent link="base_link"/>
  <child link="right_wheel_front_1"/>
</joint>

<joint name="Revolute 7" type="continuous">
  <origin xyz="-0.175 -0.15 0.09" rpy="0 0 0"/>
  <parent link="base_link"/>
  <child link="right_wheel_behind_1"/>
  <axis xyz="0.0 1.0 0.0"/>
</joint>

<joint name="Revolute 8" type="continuous">
  <origin xyz="-0.175 0.15 0.09" rpy="0 0 0"/>
  <parent link="base_link"/>
  <child link="left_wheel_behind_1"/>
  <axis xyz="0.0 -1.0 0.0"/>
</joint>

<joint name="Rigid 9" type="fixed">
  <origin xyz="0.175 0.15 0.09" rpy="0 0 0"/>
  <parent link="base_link"/>
  <child link="left_wheel_front_1"/>
</joint>

<joint name="Rigid 10" type="fixed">
  <origin xyz="-0.16 0.0 0.39" rpy="0 0 0"/>
  <parent link="base_link"/>
  <child link="lidar_1"/>
</joint>

</robot>
